Workbook
Name _sc_030BAB0B_E5D3_4D88_BCF1_7F515BC46544: Performance!$F$95
Name _sc_5A374052_E185_46EA_A244_FD64BEF8FB39: NA()
Name _Toc321998231: #REF!
Name _Toc321998232: #REF!
Name _Toc321998235: Performance!#REF!
Name _Toc321998238: #REF!
Name _Toc321998240: #REF!
Name _Toc321998241: #REF!
Name _Toc321998242: #REF!
Name _Toc329613520: #REF!
Name _Toc329613521: #REF!
Name _Toc329613522: #REF!
Name _Toc329613525: Performance!#REF!
Name _Toc329613526: Performance!$B$164
Name _Toc329613527: Performance!$B$146
Name _Toc329613530: #REF!
Name _Toc329613531: #REF!
Name _Toc329613532: #REF!
Name _Toc329613533: #REF!
Name _Toc329613534: #REF!
Name _Toc329613539: #REF!
Name _Toc467444151: #REF!
Name _Toc468848071: #REF!
Name Concurrent_user: Performance!#REF!
Name concurrent_users: Performance!#REF!
Name Data_retention: NA()
Name Data_Retention_and_Archival: Performance!$B$149:$D$149
Name Expected_growth_in_users: Performance!#REF!
Name Expected_number_of_concurrent_users: Performance!#REF!
Name Growth_User: Performance!#REF!
Name Growth_users: Performance!#REF!
Name Per_Browser: NA()
Name PerfTablesLimiter: Data_Constants!$A$3:$E$22
Name Response_Time_Requirements___Business_Services: Performance!#REF!
Name Response_Time_Requirements___Test_Harness_Transactions: NA()
Name Response_Time_Requirements___Transactions: NA()
Name Response_Time_Requirements_Transactions: NA()
Name Target_of_number_of_transactions_queries: Performance!#REF!
Name Time_SQP_event: Performance!#REF!
Name Time_SQP_trans: Performance!#REF!
Name Time_test_harness: NA()
Name Time_web: Performance!$D$76
Name Transaction: Performance!#REF!
Name Web_avail: #REF!
Name Web_avail_back: #REF!

Sheet Cover Page
B2: This is a mandatory cover page to be added to all files created within the IP&E Group. Do not delete this information.
B3: Document Name | C3: IPnE_SPD_Performance_QOPD
B4: Version No | C4: V4.1.0
B5: Document Type | C5: Requirements Review Template
B7: Author | C7: Seji Thomas, Sweety Sunny, Binu S, Kavinraj M
B8: Approver | C8: Internal Team Review
B9: Authoring Group | C9: IP&E_SPD
B11: Last version released on | C11: Oct | D11: 2024
B12: Intended Audience | C12: Architects, Technical Leads, Developers, Engineering team, Performance CoE & Testing teams.
B14: File Name | C14: IPnE_SPD_Performance_QOPD_Requirements Review Template_V4.1.0_Oct-2024.xlsx
B16: Confidentiality Statement
B18: This is a controlled document. Unauthorized access, copying, and replication are prohibited.
B19: This document must not be copied in whole or in part by any means, without the written authorization of the Delivery Excellence Head – CEG.

Sheet Read me
A1: Document History
A2: Name of the Artifact | B2: IPnE_SPD_Performance_QOPD_Requirements Review Template_V4.1.0_Oct-2024.xlsx
A3: Release Date | B3: 45582
A5: Revision History
A6: Date | B6: Release No. | C6: Remarks
A7: 45582 | B7: 4.1.0 | C7: 1. Auto-approval has been extended for Desktop type application. 2. Auto-approval has been extended for applications deployed in Cloud SAAS and PAAS, which is on top of IAAS, 3. In the 'Asset Info' tab, for the question on Technology Stack, the following new entries have been added - Gen AI and Microservices, 4. A new condition check is added to the validation logic linked with 'Response Times - Data Requirements' table to check if remarks is provided when the count of records in the table is less than 100. In such a case, positive validation will occur if the remarks are provided. The validation outcome message is also changed to reflect that the rationale for less than 100 records in the table is not provided whenever a negative validation outcome results. 5. Fixed the following issues I. In the case when online transaction table is empty (i.e., without any transaction), the validation to check if the User Concurrency distribution is proper across online transactions and online report transactions as a whole was not happening. This was fixed, and the linked changes required in the validation messages and their formatting have been made. II. The App server, Webserver, and DB server List validations were refactored to avoid making changes in the validation logic whenever the list was updated.
A8: 45504 | B8: 4.0.0 | C8: 1. Introduced additional set of Servers applicable for rule evaluation in the Web Server Pool, 2. Introduced additional set of Servers applicable for rule evaluation in the Application Server Pool, 3. Introduced additional set of Servers applicable for rule evaluation in the DB Server Pool, 4. Expanded the range of concurrent users applicable for rule evaluation. From 15 to 150, the range has been expanded to between 1 and 200, 5. In the 'Response Times - Data – Requirements' table, the column heading for 'Estimated No. Of Records per table' has been updated to imply that the number of records mentioned must be of the Performance testing environment. The Input Message in that column has also been changed to inform the end user about this expectation so while filling the performance requirements of the target asset, it is clear on what data must be filled. 6. Prevent a spill error occurring in 'Deployment Requirements' table validation due to an extra entry added between Web Server and App Server line items in the 'Software Stack - Information' table.
A9: 45299 | B9: 3.1.0 | C9: 1. Cross table data dependency validations are added 2. Allow a scenario where "Response Times - Online Txns-Requirements" table is empty In the previous release of the QOPD, an Applications with no requirements in this table, results in an error message and "Not Appproved" outcome for the table in the "Report" sheet. With the change, it allows this table to be empty when any one of "Response Times - Batch Jobs-Requirements"/"Response Times - Reports-Requirements" tables, or both are non-empty with respect to requirements. 3. Validation messages across tables that must reflect the same context have been re-written for uniformity E.g., messages such as "No batch jobs are defined" and "Response time Report requirements are not filled" 4. Changes to basic validation and message output for couple requirements tables and conditional formatting changes 5. Changes or addition in Usage guidelines ("Read me" tab)
A10: 45211 | B10: 3.0.0 | C10: 1. Allow deployments in Cloud-IAAS (GCP/ AWS/ Azure) for auto approval of requirements similar to on-premise deployments 2. Added the following in the 'Asset Info' tab i. In 'Asset Information' table, separate rows for 'Asset Name' and 'Version', ii. In 'Asset Information' table, a new row for 'Brand Name', iii. In 'Technical Details' table, added the following questions a. Which is the Geographic location of the cloud datacenter? b. Is the response time requirement Transaction wise or request wise? c. Is the expected response/ completion time SLA of all online, report, and batch transactions of the asset known? 3. Modified the following i. In 'Response Times - Data – Requirements' table, the column header for upper limit for the table size, expects data to be filled in unit of mega bytes (MB) ii. Disallow comma (',') character in 'Name' and 'Version' fields of 'Software Stack - Information' table. iii. Content in the requirements table - 'Data Management – Requirements' 4. Fixed the following issues i. If 'DB Server' cell placeholder in 'Deployment Requirements' table is having 'NA' values for 'Number of Instances'/ 'CPU cores'/ 'RAM in GB' with remarks under 'Remarks'column, it is wrongly interpreted as application with no DB, and showing wrong validation message for 'Response Times - Data – Requirements' and 'Data Management – Requirements' tables. ii. In 'Response Times - Online Txns – Requirements' table, incorrect data validations for SLA/ USLA fields. iii. Validation error is not shown when concurrent users distribution is done with 0 users.
A11: 45160 | B11: 2.0.5 | C11: 1. When either of the 'Software Stack - Information' or the 'Deployment Requirements' table is missing data related to DB Server or DB Software, alert the user with the validation message to enter missing details. 2. In 'Response Times - Online Txns – Requirements' table, validation and message display for the case when response time is above 5 secs are refactored for ensuring correctness. 3. In 'Data – Requirements' table, data is not required to be filled if DB component is not part of the asset. 4. In 'Data Management – Requirements' table, data is not required to be filled if DB component is not part of the asset. 5. In 'Data Management – Requirements' table, the case where a 'NA' value in column 'D' (Requirement) was resulting in exclusion of the corresponding row of the table for validation checks is remediated. 5. In 'Data Management – Requirements' table, the case where a 'NA' value in column 'D' (Requirement) was resulting in exclusion of the corresponding row of the table for validation checks is remediated.
A12: 45127 | B12: 2.0.4 | C12: Include editable rows in 'Deployment Requirements' and 'Channels - Information' tables. Proper naming for Apache family web server in the 'Software Stack - Information' table. Exclude the need for having a Web Server in the deployment stack for considering it as a Web-based data-centric Application.
A13: 45120 | B13: 2.0.3 | C13: Refactor of the filter function that extracts asset information and addition of an experimental validation to check if there are requirements outside of auto-approval.
A14: 45114 | B14: 2.0.2 | C14: Extending the deployment Requirements table validation and change the data validation error message in 'Data – Requirements' table, aligned to the purpose of validation .
A15: 45111 | B15: 2.0.1 | C15: Changes for concurrent users range validation auto-approval
A16: 45103 | B16: 2 | C16: © Copyright [2023], Tata Consultancy Services Limited. All Rights Reserved. Document ID CGFR009395
A17: 45084 | B17: 2 | C17: Revised Release of the document
A18: 43263 | B18: 1.31 | C18: Revised Release of the document
A19: 41512 | B19: 1.2 | C19: Formal Release of the document
A21: Usage Guidelines
A22: • This template enables self-review of performance requirements, thereby improving the quality of performance requirements that are captured. • The 'Asset Info' tab must be filled by the asset team (provide details in the 'Asset Information' and 'Technical Details of the Asset' tables) The 'Performance' tab is the main tab where all performance requirements must be provided by the asset team in the respective tables. • As the asset team enters the data in the above mentioned tabs, front-end data validations at the cell level are triggered to ensure that the user provides the right type of data and the set of constraints. • Data entered by the user is also validated based on additional rules configured for checking data correctness at the table level and across tables. Such rule adherence and violations are displayed on the right side of the respective table. • Validations at the cell level, table level, and across tables must be completed successfully for the 'QOPD Evaluation Status' in the 'Report' tab to be ready for 'Cleared' status. • The 'Report' tab consists of the outcome of automated rule validations. Results of individual rule evaluations are presented, and the consolidated status of whether the QOPD has passed through automated review is displayed.
A24: Recommendations while filling the sheet
A25: • By default, the QOPD template is filled with the requirements of a sample application. This enables asset teams to understand how the template is filled so that the teams can provide requirements for their specific software asset. Asset teams must ensure that performance requirements and other information related to the specific asset are entered, and all requirements from the sample QOPD are deleted before the QOPD is submitted for further processing.
A26: • While filling this sheet from an existing Performance QOPD, associates may opt for copying and pasting data under corresponding tables. As a result, formatting changes may also get copied and reflected in the rows copied, which can affect the front-end and additional validations configured in this template. For e.g., if the cell being copied is in 'Percentage' format, the target cell where it is copied will also change to that format. If the target cell's expected format is 'Number' format, after copying & pasting the value it changes to 'Percentage' format; as a result, the validation will fail to show the desired outcome. Overcoming the issue: Right-click the cell where the incorrect format is observed. Select 'Number format...', and change the category to 'Number', setting the decimal places as 0.
A27: • Sometimes after a copy-paste attempt, front-end validations are not triggered, and it may prevent other validations from running. Overcoming the issue: Double-click within the copied cells to trigger validations.
A28: • While filling the requirements what are the general precautions to be taken? Recommendation: 1. If data validation exists for a particular column of the table, follow the guidance in the input message. 2. If the requirement is not known, as in the case of columns with no validation, leave that column blank. 3. If available, provide 'Req-Id' field value from the Architecture document, else use the convention followed in this QOPD sheet. 4. Do not alter the contents of the table in individual or merged cells that are highlighted in shades of Maroon, Black/Gray. 5. If additional rows are required under a table to complete the requirement, insert rows within the bordered region of the table. 6. Do not directly copy paste rows/columns/cell/s directly within or from another copy of the QOPD. Instead, copy paste to a notepad. Subsequently, use that as the source to put the contents in to QOPD sheet. 7. While doing a copy paste, ensure that data is pasted to the right rows and columns. 8. Ensure that columns on an entity's description are filled mandatorily. A row with an empty description column will be excluded from the requirements. This rule applies to the following columns (refer the 'Performance' tab) i. 'Transaction Description' column of 'Response Times - Online Txns – Requirements' table ii. 'Batch job/Transaction Description' column of 'Response Times - Batch Jobs – Requirements' table iii. 'Report type (adhoc/scheduled)' column of 'Response Times - Reports – Requirements' table iv. 'Transaction Description (either Online, Batch, or Report)' column of 'Response Times - Data – Requirements' table
A29: • What must be done if requirements in the following tables are not applicable to the asset? 1. Response Times - Online Txns – Requirements 2. Response Times - Batch Jobs – Requirements 3. Response Times - Reports – Requirements 4. Response Times - Data – Requirements Recommendation: Provide 'NA' against the 'Req-Id' column in the first row. Any additional information/ context can be provided in the 'Remarks' column of the same row of the corresponding table.
A30: • Auto-approval of requirements is applicable if the following conditions are met for the asset. 1. The application is a traditional 3-tier application (having a deployment comprising of traditional Servers - Web Server, Application Server, and Database Server). 2. The number of concurrent users targeted for testing is within the range 1-200. 3. The deployment environment is on-premise dedicated VMs or IaaS (Infrastructure as a Service) Cloud VMs. 4. Irrespective of whether the deployment environment is on-premise/ cloud, if the application does not require load-balancing/ clustering strategy for supporting the load requirements.
A31: File format: The auto-review features in the QOPD template work based on formulae developed for use by Microsoft Excel. The formuale that are used in the template are being verified for the version - Office 365 Pro Plus version: 2304. It has been observed that some of the formulae that are used does not work if the QOPD sheet is opened in the following spreadsheet software, 1. Office 365 Pro Plus version: 1902 2. Google Sheet 3. Apache OpenOffice Calc that are also used by asset teams within TCS at the time of this writing. Hence use the suggested version of Office 365.
A40: QOPD naming convention: Follow the naming convention for the QOPD file -> '<OU Name>_<Asset Name>_<Version>_<NFR Assessment area>_QOPD_<Month>_<Year>.<File Extension>'. As an example, for a QOPD review request raised for a software asset with the following details in the service management portal (IPAM) OU Name: Network Solutions Group Asset Name with version: Rapid Miner v1.0 Service Name: Performance QOPD Month & Year of raising the review request: November 2023 the file name will be 'Network Solutions Group_Rapid Miner_v1-0_Performance_QOPD_Nov_2023'

Sheet Asset Info
A2: Asset Information
A3: Asset Name | B3: CodeA11y | E3: =Data_Validations!E3
A4: Version | B4: v0.0.1 | E4: =Data_Validations!E35
A5: Description | B5: CodeA11y is a VS Code extension and companion Node.js/Express server for automated WCAG 2.1 accessibility analysis. It uses Azure OpenAI to audit source files (React/Angular/Vue/Svelte/HTML) for accessibility violations, generates remediation recommendations, and produces VPAT conformance reports. The server provides JWT authentication, LLM request proxying, user governance, budget controls, audit logging, and project dashboard synchronisation. Targets enterprise development teams needing WCAG A/AA compliance integrated into their VS Code workflow. | E5: =Data_Validations!E4
A6: Brand Name | B6: TCS | E6: =Data_Validations!E36
A7: Target Customer(s) | B7: Enterprise development teams and software engineers who use VS Code and require automated WCAG accessibility compliance checking integrated into their development workflow.
A8: TCS Unit | B8: IP&E SPD
A9: Location | B9: Provide the Product team location
A10: Product/ Account Owner | B10: IP&E SPD Team
A11: TIPAR ID | B11: TBD - Obtain from IPAM before submission | E11: =Data_Validations!E39
A13: Provide the technical details of the Asset, answering the following questions
A14: Technical Details of the Asset
A15: Sl.No. | B15: Question | C15: Response | D15: Remarks | E15: Note
A16: 1 | B16: Which deployment category does the asset belong? (Standalone Desktop, On-premise Web, Cloud) | C16: Cloud | E16: If the asset does not belong to any of the given types, set it as 'Others' and provide the new category name in 'Remarks' column with a short explanation following the name.
A17: 2 | B17: If the asset is deployed in Cloud, provide the Cloud vendor's name (AWS, Azure, Google Cloud, IBM, Vistara) | C17: Azure | E17: If the deployment environment is none among the given names, set it as 'Others' and provide the vendor name in 'Remarks' column with a short explanation following the name. If it does not apply, set is as 'NA'
A18: 3 | B18: If the asset is deployed in Cloud, which is Cloud Computing Stack modeled for the asset? (IAAS, PAAS, SAAS) | C18: PAAS | E18: Provide the right choice of Cloud Computing Stack model. If it does not apply, set is as 'NA'
A19: 4 | B19: Which is the Geographic location of the cloud datacenter? | C19: Azure East US | E19: Provide geographic location of the cloud datacenter
A20: 5 | B20: Irrespective of On-premise web/ Cloud, is the asset deployment architecture following a load balancing and clustering strategy? (Yes/ No) | C20: No
A21: 6 | B21: If the asset is following load balancing and clustering strategy, how does it scale? (Auto-scaling VM instance pool, Auto-scaling Containers) | C21: NA | E21: If the load balancing and clustering strategy is none among the given strategies, set it as 'Others' and provide the strategy name in the 'Remarks' column with a short explanation following the name. If it does not apply, set is as 'NA'
A22: 7 | B22: Technology Stack applicable to the asset (Normal Web, Big Data, Blockchain, AI-ML, IoT, Google API - Firebase, Power BI, Salesforce.com, SAP-based, AR-VR, Video Recording/ Streaming) | C22: AI-ML
A23: 8 | B23: Application Type applicable to the asset (Web-based, Desktop, Mobile, API-based, Web Services, Batch, Rich client) | C23: Web-based
A24: 9 | B24: Is the response time requirement Transaction wise or request wise? | C24: Request wise | E24: How the response time should be captured? Transaction wise or request wise?
A25: 10 | B25: Is the expected response/ completion time SLA of all online, report, and batch transactions of the asset known? | C25: Yes | E25: If the expected SLA is known, performance testing results will be checked for compliance with the requirements (whether the transaction passed or failed the SLA criterion). If the expected SLA is unknown, performance testing results will have only the tested response time value and not the pass/ fail information. In either case Performance testing report will be published, and subsequently the asset will be considered for review and scoring certification.

Sheet Performance
B3: Provide the deployment data to the extent it is known. Usually, this information is available if there is already an existing asset that will be replaced by this asset.
B4: Deployment Requirements | I4: =Data_Validations!E5
B5: Server | C5: Number of Instances | D5: CPU cores | E5: RAM in GB | F5: Remarks | I5: =Data_Validations!E34
B6: Web Server | C6: 1 | D6: 2 | E6: 4 | I6: =Data_Validations!E37
I7: =Data_Validations!E38
B8: Application Server | C8: 1 | D8: 2 | E8: 4
B10: Content/Image server | C10: 1 | D10: 2 | E10: 4 | F10: Static portal assets served directly by Node.js/Express; no separate content/image server
B12: DB Server | C12: 1 | D12: 2 | E12: 8
B20: Mention if the product needs to work in alternative technologies as well
B21: Software Stack - Information | I21: =Data_Validations!E6
B22: Server | C22: Category | D22: Name | E22: Version | F22: Remarks | I22: =Data_Validations!E7
B23: Software - Web Server | C23: Web server (e.g. Apache) | D23: Node.js + Express | E23: 4.18.2
B27: Application Server | C27: Application Server (e.g Jboss) | D27: Node.js | E27: 24.11.0
C29: Language (e.g JDK) | D29: TypeScript | E29: 5.3.0
C31: Javascript libraries/packages (extJs etc) | D31: VS Code Extension API | E31: 1.85.0
C33: Frameworks (e.g Spring, Struts…) | D33: Express | E33: 4.18.2
C35: Logging
C37: Middleware (e.g JMS …) | D37: Helmet + express-rate-limit | E37: 7.1.0 / 7.5.0
C39: Search Engine
C41: Content Mgmt system
C43: 3rd party products (e.g SMS gateway etc) | D43: Playwright (runtime page analysis) | E43: 1.60.0
D44: OpenAI SDK (Azure OpenAI proxy client) | E44: 6.18.0
D45: jsonwebtoken | E45: 9.0.2
D46: multer (VSIX upload handling) | E46: 2.2.0
D47: sql.js (SQLite dev / no-DB mode) | E47: 1.13.0
B53: DB Server | C53: DB Server (e.g. MySQL) | D53: Postgres | E53: 16
B58: Concurrent users is the count of users who are in the middle of business transactions at any given time. Note that a business transaction can consist of multiple web pages.
B59: User Types – Requirements | I59: =Data_Validations!E8
B60: User types available in the system (e.g Admins, customers, Supervisors etc) | C60: Total number of users of each type (whether using the system or not). i.e the expected population | D60: How many users are concurrently doing a transaction during peak usage time? | E60: Concurrent user % growth - Year 3 | F60: Concurrent user % growth - Year 5 | G60: Remarks
B61: Admin | C61: 2 | D61: 1 | E61: NA | F61: NA
B62: Developer (VS Code Extension User) | C62: 100 | D62: 50 | E62: 20 | F62: 30
B71: All the modes of accessing the asset
B72: Channels - Information | I72: =Data_Validations!E9
B73: Category | C73: What % of users will access this channel? (note - sum of percentages must remain 100) | D73: Remarks
B74: Web | C74: 30
B75: Call Centre | C75: NA
B76: Email | C76: NA
B77: Social Media | C77: NA
B78: Mobile | C78: NA
B79: Desktop | C79: 70
...

Sheet Data_Validations
B2: Sl. No. | C2: Table | D2: Validation Rule | E2: Validation Message | F2: Validation Status | H2: Sl. No. | I2: Validation Rule | J2: Validation Message | K2: Validation Staus | M2: Has Web Server? | N2: Has Application Server? | O2: Has DB Server? | P2: Programming Language? | T2: Deployment Category | U2: LB & Clustering Strategy | V2: Auto-scaling Strategy | W2: Technology Stack | X2: Application Type | Y2: Concurrent User Distribution If it is a Desktop Application
B3: 1 | C3: Asset Information | D3: =Data_Constants!C101 | E3: =IF(LEN(B51)>=Data_Constants!N5, Data_Constants!C75, Data_Constants!D75) | F3: =IF(E3=Data_Constants!D75, FALSE, TRUE) | H3: 1 | I3: Checks if the Application Software Stack has Web, App, and DB Servers | J3: {=_xlfn.LET(_xlpm.hasWebserver, M3, _xlpm.hasAppserver, N3,_xlpm.hasDbserver, O3, IF(AND(_xlpm.hasAppserver, _xlpm.hasDbserver), INDEX(Table_Messages[Valid case Message],21),INDEX(Table_Messages[Invalid case Message],21)))} | K3: =IF(J3=Data_Constants!D49, FALSE, TRUE) | M3: {=_xlfn.LET( _xlpm.fullrnge1, INDIRECT(CONCATENATE("Performance!B",Data_Constants!N25,":F", Data_Constants!N25)), _xlpm.softwarestackColumnrnge, INDIRECT(CONCATENATE("Performance!D",Data_Constants!N25,":D", Data_Constants!N25)), _xlpm.WebServerRange, INDIRECT(CONCATENATE("Data_Constants!AI3",":AI33")), _xlpm.WebServerCheckOutcomeList, COUNTIF(_xlpm.softwarestackColumnrnge,"*"&_xlpm.WebServerRange&"*"), _xlpm.hasWebServer, IF(MAX(_xlpm.WebServerCheckOutcomeList)=0,FALSE, TRUE), _xlpm.hasWebServer)} | N3: {=_xlfn.LET( _xlpm.fullrnge1, INDIRECT(CONCATENATE("Performance!B",Data_Constants!N27+1,":F", Data_Constants!N27+1)), _xlpm.softwarestackColumnrnge, INDIRECT(CONCATENATE("Performance!D",Data_Constants!N27+1,":D", Data_Constants!N27+1)), _xlpm.AppServerRange, INDIRECT(CONCATENATE("Data_Constants!AF3",":AF36")), _xlpm.AppServerCheckOutcomeList, COUNTIF(_xlpm.softwarestackColumnrnge,"*"&_xlpm.AppServerRange&"*"), _xlpm.hasAppServer, IF(MAX(_xlpm.AppServerCheckOutcomeList)=0,FALSE, TRUE), _xlpm.hasAppServer)} | O3: {=_xlfn.LET(_xlpm.fullrnge1, INDIRECT(CONCATENATE("Performance!B",Data_Constants!N20,":F", Data_Constants!N20)),_xlpm.softwarestackColumnrnge, INDIRECT(CONCATENATE("Performance!D",Data_Constants!N20,":D", Data_Constants!N20)), _xlpm.DBServerRange, INDIRECT(CONCATENATE("Data_Constants!AC3",":AC32")), _xlpm.DBServerCheckOutcomeList, COUNTIF(_xlpm.softwarestackColumnrnge,"*"&_xlpm.DBServerRange&"*"), _xlpm.hasDbServer, IF(MAX(_xlpm.DBServerCheckOutcomeList)=0,FALSE, TRUE), _xlpm.hasDbServer)} | T3: {=_xlfn.LET(_xlpm.minindex, MATCH(Data_Constants!C7, $V$2:$V$300,0)+3,_xlpm.fullcolumnrnge, INDIRECT(CONCATENATE("V",_xlpm.minindex,":V300")), _xlpm.maxindex, MIN(IF(_xlpm.fullcolumnrnge="",ROW(_xlpm.fullcolumnrnge)))-1, _xlpm.usertypesColumnrnge, INDIRECT(CONCATENATE("V",_xlpm.minindex,":V",_xlpm.maxindex)), _xlpm.totalusersColumnrnge, INDIRECT(CONCATENATE("W",_xlpm.minindex,":W",_xlpm.maxindex)), _xlpm.concusersColumnrnge, INDIRECT(CONCATENATE("X",_xlpm.minindex,":X",_xlpm.maxindex)), _xlpm.rnge1, IF(SUM(VALUE(_xlpm.concusersColumnrnge))= 1, 1,0), OR(('Asset Info'!C16=Data_Constants!K50),AND(('Asset Info'!C16=Data_Constants!K51), OR(('Asset Info'!C17=Data_Constants!H57),('Asset Info'!C17=Data_Constants!H58),('Asset Info'!C17=Data_Constants!H59)), OR(('Asset Info'!C18=Data_Constants!K60),('Asset Info'!C18=Data_Constants!K61),('Asset Info'!C18=Data_Constants!K62))), AND(('Asset Info'!C16=Data_Constants!K49), MIN(_xlpm.rnge1)=1)))} | U3: =('Asset Info'!C20=Data_Constants!H69) | V3: =('Asset Info'!C21=Data_Constants!K72) | W3: =('Asset Info'!C22=Data_Constants!H75) | X3: =('Asset Info'!C23=Data_Constants!K78) | Y3: {=_xlfn.LET(_xlpm.minindex, MATCH(Data_Constants!C7, $V$2:$V$300,0)+3,_xlpm.fullcolumnrnge, INDIRECT(CONCATENATE("V",_xlpm.minindex,":V300")), _xlpm.maxindex, MIN(IF(_xlpm.fullcolumnrnge="",ROW(_xlpm.fullcolumnrnge)))-1, _xlpm.usertypesColumnrnge, INDIRECT(CONCATENATE("V",_xlpm.minindex,":V",_xlpm.maxindex)), _xlpm.totalusersColumnrnge, INDIRECT(CONCATENATE("W",_xlpm.minindex,":W",_xlpm.maxindex)), _xlpm.concusersColumnrnge, INDIRECT(CONCATENATE("X",_xlpm.minindex,":X",_xlpm.maxindex)), _xlpm.rnge1, IF(SUM(VALUE(_xlpm.concusersColumnrnge))= 1, TRUE,FALSE), _xlpm.rnge1)}
B4: 2 | C4: Asset Information | D4: =Data_Constants!C102 | E4: =IF(LEN(B53)>=Data_Constants!N3, Data_Constants!C30, Data_Constants!D30) | F4: =IF(E4=Data_Constants!D30, FALSE, TRUE) | H4: 2 | I4: Checks if the user concurrency distribution is done following the laid down constraints, and if the total user concurrency for the performance assessment is greater than or equal to 15, and less than or equal to 100. | J4: {=_xlfn.LET(_xlpm.minindex1, MATCH(Data_Constants!C7, $V$2:$V$300,0)+3,_xlpm.fullcolumnrnge1, INDIRECT(CONCATENATE("V",_xlpm.minindex1,":V300")), _xlpm.maxindex1, MIN(IF(_xlpm.fullcolumnrnge1="",ROW(_xlpm.fullcolumnrnge1)))-1, _xlpm.peakallconusersColumnrnge, INDIRECT(CONCATENATE("X",_xlpm.minindex1,":X",_xlpm.maxindex1)), _xlpm.minindex2, MATCH(Data_Constants!C11, $AJ$2:$AJ$300,0)+3,_xlpm.fullcolumnrnge2, INDIRECT(CONCATENATE("AJ",_xlpm.minindex2,":AJ300")), _xlpm.t_maxindex2, MIN(IF(_xlpm.fullcolumnrnge2="",ROW(_xlpm.fullcolumnrnge2)))-1, _xlpm.maxindex2, IF(_xlpm.t_maxindex2 < _xlpm.minindex2, _xlpm.minindex2, _xlpm.t_maxindex2), _xlpm.onlinetxnconusersColumnrnge, IF(_xlpm.t_maxindex2 < _xlpm.minindex2, 0, INDIRECT(CONCATENATE("AP",_xlpm.minindex2,":AP",_xlpm.maxindex2))), _xlpm.minindex3, MATCH(Data_Constants!C14, $BJ$2:$BJ$300,0)+3,_xlpm.fullcolumnrnge3, INDIRECT(CONCATENATE("BJ",_xlpm.minindex3,":BJ300")), _xlpm.t_maxindex3, MIN(IF(_xlpm.fullcolumnrnge3="",ROW(_xlpm.fullcolumnrnge3)))-1, _xlpm.maxindex3, IF(_xlpm.t_maxindex3 < _xlpm.minindex3, _xlpm.minindex3, _xlpm.t_maxindex3), _xlpm.onlinerptconusersColumnrnge, IF(_xlpm.t_maxindex3 < _xlpm.minindex3, 0, INDIRECT(CONCATENATE("BS",_xlpm.minindex3,":BS",_xlpm.maxindex3))), _xlpm.maxConcusers, IF(AND(ISNUMBER(_xlpm.peakallconusersColumnrnge),ISNUMBER(_xlpm.onlinetxnconusersColumnrnge),ISNUMBER(_xlpm.onlinerptconusersColumnrnge)), IF(SUM(_xlpm.peakallconusersColumnrnge)>=SUM(_xlpm.onlinetxnconusersColumnrnge)+SUM(_xlpm.onlinerptconusersColumnrnge), SUM(_xlpm.peakallconusersColumnrnge), -1), -1), IF(_xlpm.maxConcusers>=Data_Constants!N10, IF(_xlpm.maxConcusers<=Data_Constants!N11, Data_Constants!C50, Data_Constants!D50), Data_Constants!D50))} | K4: =IF(J4=Data_Constants!D50, FALSE, TRUE) | M4: {=_xlfn.LET( _xlpm.fullrnge1,INDIRECT(CONCATENATE("Performance!B",Data_Constants!N25,":F",Data_Constants!N25)), _xlpm.softwarestackColumnrnge,INDIRECT(CONCATENATE("Performance!D",Data_Constants!N25,":D",Data_Constants!N25)),_xlpm.softwareversCol,INDIRECT(CONCATENATE("Performance!E",Data_Constants!N25,":E",Data_Constants!N25)),_xlpm.WebServerRange,INDIRECT(CONCATENATE("Data_Constants!AI3",":AI33")),_xlpm.WebServerCheckOutcomeList,COUNTIF(_xlpm.softwarestackColumnrnge,"*"&_xlpm.WebServerRange&"*"),IF(MAX(_xlpm.WebServerCheckOutcomeList)=0,"",_xlpm.softwarestackColumnrnge&" "&_xlpm.softwareversCol))} | N4: {=_xlfn.LET( _xlpm.fullrnge1, INDIRECT(CONCATENATE("Performance!B",Data_Constants!N27+1,":F", Data_Constants!N27+1)), _xlpm.softwarestackColumnrnge, INDIRECT(CONCATENATE("Performance!D",Data_Constants!N27+1,":D", Data_Constants!N27+1)), _xlpm.softwareversCol, INDIRECT(CONCATENATE("Performance!E",Data_Constants!N27+1,":E", Data_Constants!N27+1)), _xlpm.AppServerRange, INDIRECT(CONCATENATE("Data_Constants!AF3",":AF36")), _xlpm.AppServerCheckOutcomeList, COUNTIF(_xlpm.softwarestackColumnrnge,"*"&_xlpm.AppServerRange&"*"), IF(MAX(_xlpm.AppServerCheckOutcomeList)=0,"",_xlpm.softwarestackColumnrnge&" "&_xlpm.softwareversCol))} | O4: {=_xlfn.LET(_xlpm.fullrnge1, INDIRECT(CONCATENATE("Performance!B",Data_Constants!N20,":F", Data_Constants!N20)),_xlpm.softwarestackColumnrnge, INDIRECT(CONCATENATE("Performance!D",Data_Constants!N20,":D", Data_Constants!N20)), _xlpm.softwareversCol, INDIRECT(CONCATENATE("Performance!E",Data_Constants!N20,":E", Data_Constants!N20)), _xlpm.DBServerRange, INDIRECT(CONCATENATE("Data_Constants!AC3",":AC32")), _xlpm.DBServerCheckOutcomeList, COUNTIF(_xlpm.softwarestackColumnrnge,"*"&_xlpm.DBServerRange&"*"), IF(MAX(_xlpm.DBServerCheckOutcomeList)=0,"",_xlpm.softwarestackColumnrnge&" "&_xlpm.softwareversCol))} | P4: {=_xlfn.LET(_xlpm.fullrnge1, INDIRECT(CONCATENATE("Performance!B",Data_Constants!E5,":F", Data_Constants!E6)), _xlpm.softwarestackColumnrnge, INDIRECT(CONCATENATE("Performance!D",Data_Constants!E5,":D", Data_Constants!E6)), _xlpm.filteredfullrange, _xlfn._xlws.FILTER(_xlpm.fullrnge1, ISNUMBER(SEARCH(""&Data_Constants!H49&"", _xlpm.softwarestackColumnrnge))+ISNUMBER(SEARCH(""&Data_Constants!H50&"", _xlpm.softwarestackColumnrnge)), INDIRECT(CONCATENATE("A9999",":F9999"))), _xlpm.softwareCol, _xlfn.CHOOSECOLS(_xlpm.filteredfullrange, 3), _xlpm.softwareversCol, _xlfn.CHOOSECOLS(_xlpm.filteredfullrange, 4), _xlpm.softwareCol&" "&_xlpm.softwareversCol)}
B5: 3 | C5: Deployment Requirements | D5: =Data_Constants!C103 | E5: {=_xlfn.LET(_xlpm.fullcolumnrnge, INDIRECT(CONCATENATE("H50",":H300")), _xlpm.minindex, MATCH(Data_Constants!C3, $H$2:$H$300,0)+3, _xlpm.maxindex, MIN(IF(_xlpm.fullcolumnrnge="",ROW(_xlpm.fullcolumnrnge)))-1, _xlpm.serverColumnrnge, INDIRECT(CONCATENATE("H",_xlpm.minindex,":H",_xlpm.maxindex)), _xlpm.numInstancesrnge, INDIRECT(CONCATENATE("I",_xlpm.minindex,":I",_xlpm.maxindex)), _xlpm.cpuCoresrnge, INDIRECT(CONCATENATE("J",_xlpm.minindex,":J",_xlpm.maxindex)), _xlpm.ramCaprnge, INDIRECT(CONCATENATE("K",_xlpm.minindex,":K",_xlpm.maxindex)), IF(AND(NOT(ISBLANK(_xlpm.serverColumnrnge)),_xlpm.serverColumnrnge<>0, NOT(ISBLANK(_xlpm.numInstancesrnge)), _xlpm.numInstancesrnge<>0,NOT(ISBLANK(_xlpm.cpuCoresrnge)),_xlpm.cpuCoresrnge<>0, NOT(ISBLANK(_xlpm.ramCaprnge)),_xlpm.ramCaprnge<>0, IF(ISNUMBER(_xlpm.numInstancesrnge), IF(ISNUMBER(_xlpm.cpuCoresrnge), 1, 0), IF(_xlpm.cpuCoresrnge="NA", 1, 0)), IF(ISNUMBER(_xlpm.numInstancesrnge), IF(ISNUMBER(_xlpm.ramCaprnge), 1, 0), IF(_xlpm.ramCaprnge="NA", 1, 0)), IF(AND(E34=Data_Constants!C70,E37=Data_Constants!C79,E38=Data_Constants!C82),1,0)), Data_Constants!C31, Data_Constants!D31))} | F5: =IF(E5=Data_Constants!D31, FALSE, TRUE) | H5: 3 | I5: Checks if the Application is a normal web application based on the answer to the questionnaire in the 'Asset Info' sheet | J5: {=_xlfn.LET(_xlpm.deplomentCategoryAllowed, T3, _xlpm.lbcStrategyAllowed, U3,_xlpm.autoScaleAllowed, V3, _xlpm.techStackAllowed, W3, _xlpm.appTypeAllowed, X3,IF(AND(_xlpm.deplomentCategoryAllowed, _xlpm.lbcStrategyAllowed, _xlpm.autoScaleAllowed, _xlpm.techStackAllowed, _xlpm.appTypeAllowed), INDEX(Table_Messages[Valid case Message],29),INDEX(Table_Messages[Invalid case Message],29)))} | K5: =IF(J5=Data_Constants!D57, FALSE, TRUE)
B6: 4 | C6: Software Stack - Information | D6: =Data_Constants!C104 | E6: {=_xlfn.LET( _xlpm.minindex, MATCH(Data_Constants!C5, $O$2:$O$300,0)+3, _xlpm.fullcolumnrnge, INDIRECT(CONCATENATE("O",_xlpm.minindex,":O300")), _xlpm.maxindex, MIN(IF(_xlpm.fullcolumnrnge="",ROW(_xlpm.fullcolumnrnge)))-1, _xlpm.softwareNameColumnrnge, INDIRECT(CONCATENATE("Q",_xlpm.minindex,":Q",_xlpm.maxindex)), _xlpm.versionNameColumnrnge, INDIRECT(CONCATENATE("R",_xlpm.minindex,":R",_xlpm.maxindex)), _xlpm.range1, IF(ISNUMBER(SEARCH(",",_xlpm.softwareNameColumnrnge)),0,1), IF(AND(COUNTBLANK(_xlpm.softwareNameColumnrnge)=0, _xlpm.versionNameColumnrnge<>0, COUNTBLANK(_xlpm.versionNameColumnrnge)=0,MIN(_xlpm.range1)=1), Data_Constants!C32, Data_Constants!D32))} | F6: =IF(E6=Data_Constants!D32, FALSE, TRUE)
B7: 5 | C7: Software Stack - Information | D7: =Data_Constants!C105 | E7: {=_xlfn.LET(_xlpm.minindex, MATCH(Data_Constants!C5, $O$2:$O$300,0)+3,_xlpm.fullcolumnrnge, INDIRECT(CONCATENATE("O",_xlpm.minindex,":O200")), _xlpm.t_maxindex, MIN(IF(_xlpm.fullcolumnrnge="",ROW(_xlpm.fullcolumnrnge)))-1, _xlpm.maxindex, IF(_xlpm.t_maxindex < _xlpm.minindex, _xlpm.minindex, _xlpm.t_maxindex), _xlpm.versionNameColumnrnge, INDIRECT(CONCATENATE("R",_xlpm.minindex,":R",_xlpm.maxindex)), _xlpm.rnge1, IF(_xlfn.VALUETOTEXT(_xlpm.versionNameColumnrnge)="NA",1, IF(_xlfn.VALUETOTEXT(_xlpm.versionNameColumnrnge)="0",0, IF(ISTEXT(_xlpm.versionNameColumnrnge), 1, IF(ISNUMBER(_xlpm.versionNameColumnrnge), 1,0)))), IF(MIN(_xlpm.rnge1)=0, Data_Constants!D33, Data_Constants!C33))} | F7: =IF(E7=Data_Constants!D33, FALSE, TRUE) | I7: Is there additional requirements out of the scope of auto-approval? | J7: =_xlfn.LET(_xlpm.sheetsinQOPD, INDIRECT(CONCATENATE("Data_Constants!H",92,":H",99)),IF(COUNTA(_xlpm.sheetsinQOPD)=_xlfn.SHEETS(), FALSE, TRUE))
B8: 6 | C8: User Types – Requirements | D8: =Data_Constants!C106 | E8: {=_xlfn.LET(_xlpm.minindex, MATCH(Data_Constants!C7, $V$2:$V$300,0)+3,_xlpm.fullcolumnrnge, INDIRECT(CONCATENATE("V",_xlpm.minindex,":V300")), _xlpm.maxindex, MIN(IF(_xlpm.fullcolumnrnge="",ROW(_xlpm.fullcolumnrnge)))-1, _xlpm.usertypesColumnrnge, INDIRECT(CONCATENATE("V",_xlpm.minindex,":V",_xlpm.maxindex)), _xlpm.totalusersColumnrnge, INDIRECT(CONCATENATE("W",_xlpm.minindex,":W",_xlpm.maxindex)), _xlpm.concusersColumnrnge, INDIRECT(CONCATENATE("X",_xlpm.minindex,":X",_xlpm.maxindex)), _xlpm.evalRnge, IF(OR(NOT(_xlfn.VALUETOTEXT(_xlpm.usertypesColumnrnge)<>""), NOT(_xlfn.VALUETOTEXT(_xlpm.totalusersColumnrnge)<>""), NOT(_xlfn.VALUETOTEXT(_xlpm.concusersColumnrnge)<>"")),0, IF(OR(NOT(_xlfn.VALUETOTEXT(_xlpm.usertypesColumnrnge)<>"0"), NOT(_xlfn.VALUETOTEXT(_xlpm.totalusersColumnrnge)<>"0")), 1, IF(NOT(ISNUMBER(_xlpm.totalusersColumnrnge)), 2, IF(NOT(ISNUMBER(_xlpm.concusersColumnrnge)), 3, IF(VALUE(_xlpm.totalusersColumnrnge)>=VALUE(_xlpm.concusersColumnrnge), 5, 4))))), IF(OR(MIN(_xlpm.evalRnge)=0,MIN(_xlpm.evalRnge)=1), Data_Constants!D52, IF(MIN(_xlpm.evalRnge)=2, Data_Constants!D53, IF(MIN(_xlpm.evalRnge)=3, Data_Constants!D54, IF(MIN(_xlpm.evalRnge)=5, Data_Constants!C34, Data_Constants!D55)))))} | F8: =IF(E8=Data_Constants!C34, TRUE, FALSE)
B9: 7 | C9: Channels - Information | D9: =Data_Constants!C107 | E9: {=_xlfn.LET(_xlpm.minindex, MATCH(Data_Constants!C9, $AD$2:$AD$300,0)+3,_xlpm.fullcolumnrnge, INDIRECT(CONCATENATE("AD",_xlpm.minindex,":AD300")), _xlpm.maxindex, MIN(IF(_xlpm.fullcolumnrnge="",ROW(_xlpm.fullcolumnrnge)))-1, _xlpm.percentofuserscolumnrnge, INDIRECT(CONCATENATE("AE",_xlpm.minindex,":AE",_xlpm.maxindex)), _xlpm.percentagesum, IF(AND( NOT(ISBLANK(_xlpm.percentofuserscolumnrnge)),ISNUMBER(_xlpm.percentofuserscolumnrnge)),SUM(VALUE(_xlpm.percentofuserscolumnrnge)), "INVALID_SUM"), IF(_xlpm.percentagesum=100, Data_Constants!C35, Data_Constants!D35))} | F9: =IF(E9=Data_Constants!D35, FALSE, TRUE)
B10: 8 | C10: Response Times - Online Txns – Requirements | D10: =Data_Constants!C108 | E10: {=_xlfn.LET( _xlpm.minindex1, MATCH(Data_Constants!C11, $AJ$2:$AJ$300,0)+3, _xlpm.fullcolumnrnge1,INDIRECT(CONCATENATE("AJ",_xlpm.minindex1,":AJ300")), _xlpm.maxindex1, MIN(IF(_xlpm.fullcolumnrnge1="",ROW(_xlpm.fullcolumnrnge1)))-1, _xlpm.txnDesccolumnrnge, INDIRECT(CONCATENATE("AK",_xlpm.minindex1,":AK",_xlpm.maxindex1)), _xlpm.addminx1, INDIRECT(CONCATENATE("AJ", _xlpm.minindex1,":AP", _xlpm.maxindex1)), _xlpm.minindex2, MATCH(Data_Constants!C13, $AW$2:$AW$300,0)+3, _xlpm.fullcolumnrnge2, INDIRECT(CONCATENATE("AW",_xlpm.minindex2,":AW300")), _xlpm.maxindex2, MIN(IF(_xlpm.fullcolumnrnge2="",ROW(_xlpm.fullcolumnrnge2)))-1, _xlpm.addminx2, INDIRECT(CONCATENATE("AW", _xlpm.minindex2,":BD", _xlpm.maxindex2)), _xlpm.minindex3, MATCH(Data_Constants!C15, $BJ$2:$BJ$300,0)+3, _xlpm.fullcolumnrnge3, INDIRECT(CONCATENATE("BJ",_xlpm.minindex3,":BJ300")), _xlpm.maxindex3, MIN(IF(_xlpm.fullcolumnrnge3="",ROW(_xlpm.fullcolumnrnge3)))-1, _xlpm.addminx3, INDIRECT(CONCATENATE("BJ", _xlpm.minindex3,":BN", _xlpm.maxindex3)), _xlpm.rnge1, IF(OR(ISBLANK(_xlpm.addminx1),(_xlfn.CHOOSECOLS(_xlpm.addminx1,1,2,5,6,7))="NA"),0,1), _xlpm.rnge2, IF(OR(ISBLANK(_xlpm.addminx2),(_xlpm.addminx2)="NA"),0,1), _xlpm.rnge3, IF(OR(ISBLANK(_xlpm.addminx3),(_xlpm.addminx3)="NA"),0,1), IF(AND(MIN(_xlpm.rnge1)=0,MIN(_xlpm.rnge2)=0,MIN(_xlpm.rnge3)=0),Data_Constants!D83, IF( AND(MIN(_xlpm.rnge1)=0,OR(MIN(_xlpm.rnge2)=1,MIN(_xlpm.rnge3)=1) ),Data_Constants!C83, IF(MIN(_xlpm.rnge1)=1,IF(AND(_xlpm.txnDesccolumnrnge<>"", LEN(_xlpm.txnDesccolumnrnge)>=Data_Constants!N7), Data_Constants!C36, Data_Constants!D36),"This will not happen"))))} | F10: =IF(OR(E10=Data_Constants!D36,E10=Data_Constants!D83,), FALSE, TRUE) | M10: {=_xlfn.LET(_xlpm.fullrnge1, INDIRECT(CONCATENATE("Performance!B",Data_Constants!E5,":F", Data_Constants!E6)), _xlpm.softwarestackColumnrnge, INDIRECT(CONCATENATE("Performance!D",Data_Constants!E5,":D", Data_Constants!E6)), _xlpm.filteredfullrange, _xlfn._xlws.FILTER(_xlpm.fullrnge1, ISNUMBER(SEARCH("*"&Data_Constants!$H$27:$H$29&"*", _xlpm.softwarestackColumnrnge)), INDIRECT(CONCATENATE("A9999",":F9999"))), _xlpm.softwareCol, _xlfn.CHOOSECOLS(_xlpm.filteredfullrange, 3), _xlpm.softwareversCol, _xlfn.CHOOSECOLS(_xlpm.filteredfullrange, 4), _xlpm.softwareCol&" "&_xlpm.softwareversCol)}
B11: 9 | C11: Response Times - Online Txns – Requirements | D11: =Data_Constants!C109 | E11: {=_xlfn.LET( _xlpm.minindex1, MATCH(Data_Constants!C11, $AJ$2:$AJ$300,0)+3, _xlpm.fullcolumnrnge1,INDIRECT(CONCATENATE("AJ",_xlpm.minindex1,":AJ300")), _xlpm.maxindex1, MIN(IF(_xlpm.fullcolumnrnge1="",ROW(_xlpm.fullcolumnrnge1)))-1, _xlpm.slaColumnrnge, INDIRECT(CONCATENATE("AN",_xlpm.minindex1,":AN",_xlpm.maxindex1)), _xlpm.addminx1, INDIRECT(CONCATENATE("AJ", _xlpm.minindex1,":AP", _xlpm.maxindex1)), _xlpm.minindex2, MATCH(Data_Constants!C13, $AW$2:$AW$300,0)+3, _xlpm.fullcolumnrnge2, INDIRECT(CONCATENATE("AW",_xlpm.minindex2,":AW300")), _xlpm.maxindex2, MIN(IF(_xlpm.fullcolumnrnge2="",ROW(_xlpm.fullcolumnrnge2)))-1, _xlpm.addminx2, INDIRECT(CONCATENATE("AW", _xlpm.minindex2,":BD", _xlpm.maxindex2)), _xlpm.minindex3, MATCH(Data_Constants!C15, $BJ$2:$BJ$300,0)+3, _xlpm.fullcolumnrnge3, INDIRECT(CONCATENATE("BJ",_xlpm.minindex3,":BJ300")), _xlpm.maxindex3, MIN(IF(_xlpm.fullcolumnrnge3="",ROW(_xlpm.fullcolumnrnge3)))-1, _xlpm.addminx3, INDIRECT(CONCATENATE("BJ", _xlpm.minindex3,":BN", _xlpm.maxindex3)), _xlpm.rnge1, IF(OR(ISBLANK(_xlpm.addminx1),(_xlfn.CHOOSECOLS(_xlpm.addminx1,1,2,5,6,7))="NA"),0,1), _xlpm.rnge2, IF(OR(ISBLANK(_xlpm.addminx2),(_xlpm.addminx2)="NA"),0,1), _xlpm.rnge3, IF(OR(ISBLANK(_xlpm.addminx3),(_xlpm.addminx3)="NA"),0,1), _xlpm.rnge4, IF(ISNUMBER(MIN(_xlpm.slaColumnrnge)), IF(MIN(_xlpm.slaColumnrnge)=0,0,1),0), IF(AND(MIN(_xlpm.rnge1)=0,MIN(_xlpm.rnge2)=0,MIN(_xlpm.rnge3)=0),Data_Constants!D83, IF(AND(MIN(_xlpm.rnge1)=0,OR(MIN(_xlpm.rnge2)=1,MIN(_xlpm.rnge3)=1) ),Data_Constants!C83, IF(AND(MIN(_xlpm.rnge1)=1, _xlpm.rnge4=1), Data_Constants!C37, IF(AND(MIN(_xlpm.rnge1)=1, _xlpm.rnge4=0), Data_Constants!D37,Data_Constants!C37 )))))} | F11: =IF(OR(E11=Data_Constants!D37,E11=Data_Constants!D83,), FALSE, TRUE)
B12: 10 | C12: Response Times - Online Txns – Requirements | D12: =Data_Constants!C110 | E12: {=_xlfn.LET( _xlpm.minindex1, MATCH(Data_Constants!C11, $AJ$2:$AJ$300,0)+3, _xlpm.fullcolumnrnge1, INDIRECT(CONCATENATE("AJ",_xlpm.minindex1,":AJ300")), _xlpm.maxindex1, MIN(IF(_xlpm.fullcolumnrnge1="",ROW(_xlpm.fullcolumnrnge1)))-1, _xlpm.uslaColumnrnge, INDIRECT(CONCATENATE("AO",_xlpm.minindex1,":AO",_xlpm.maxindex1)), _xlpm.addminx1, INDIRECT(CONCATENATE("AJ", _xlpm.minindex1,":AP", _xlpm.maxindex1)), _xlpm.minindex2, MATCH(Data_Constants!C13, $AW$2:$AW$300,0)+3, _xlpm.fullcolumnrnge2, INDIRECT(CONCATENATE("AW",_xlpm.minindex2,":AW300")), _xlpm.maxindex2, MIN(IF(_xlpm.fullcolumnrnge2="",ROW(_xlpm.fullcolumnrnge2)))-1, _xlpm.addminx2, INDIRECT(CONCATENATE("AW", _xlpm.minindex2,":BD", _xlpm.maxindex2)), _xlpm.minindex3, MATCH(Data_Constants!C15, $BJ$2:$BJ$300,0)+3, _xlpm.fullcolumnrnge3, INDIRECT(CONCATENATE("BJ",_xlpm.minindex3,":BJ300")), _xlpm.maxindex3, MIN(IF(_xlpm.fullcolumnrnge3="",ROW(_xlpm.fullcolumnrnge3)))-1, _xlpm.addminx3, INDIRECT(CONCATENATE("BJ", _xlpm.minindex3,":BN", _xlpm.maxindex3)), _xlpm.rnge1, IF(OR(ISBLANK(_xlpm.addminx1),(_xlfn.CHOOSECOLS(_xlpm.addminx1,1,2,5,6,7))="NA"),0,1), _xlpm.rnge2, IF(OR(ISBLANK(_xlpm.addminx2),(_xlpm.addminx2)="NA"),0,1), _xlpm.rnge3, IF(OR(ISBLANK(_xlpm.addminx3),(_xlpm.addminx3)="NA"),0,1), _xlpm.rnge4, IF(ISNUMBER(_xlpm.uslaColumnrnge), IF(_xlpm.uslaColumnrnge=0, 0,1)), IF(AND(MIN(_xlpm.rnge1)=0,MIN(_xlpm.rnge2)=0,MIN(_xlpm.rnge3)=0),Data_Constants!D83, IF(AND(MIN(_xlpm.rnge1)=0,OR(MIN(_xlpm.rnge2)=1,MIN(_xlpm.rnge3)=1) ),Data_Constants!C83, IF(MIN(_xlpm.rnge4)=1, Data_Constants!C38, Data_Constants!D38))))} | F12: =IF(OR(E12=Data_Constants!D38,E12=Data_Constants!D83,), FALSE, TRUE)
B13: 11 | C13: Response Times - Online Txns – Requirements | D13: =Data_Constants!C111 | E13: {=_xlfn.LET( _xlpm.minindex1, MATCH(Data_Constants!C11, $AJ$2:$AJ$300,0)+3, _xlpm.fullcolumnrnge1, INDIRECT(CONCATENATE("AJ",_xlpm.minindex1,":AJ300")), _xlpm.maxindex1, MIN(IF(_xlpm.fullcolumnrnge1="",ROW(_xlpm.fullcolumnrnge1)))-1, _xlpm.slaColumnrnge, INDIRECT(CONCATENATE("AN",_xlpm.minindex1,":AN",_xlpm.maxindex1)), _xlpm.uslaColumnrnge, INDIRECT(CONCATENATE("AO",_xlpm.minindex1,":AO",_xlpm.maxindex1)), _xlpm.addminx1, INDIRECT(CONCATENATE("AJ", _xlpm.minindex1,":AP", _xlpm.maxindex1)), _xlpm.minindex2, MATCH(Data_Constants!C13, $AW$2:$AW$300,0)+3, _xlpm.fullcolumnrnge2, INDIRECT(CONCATENATE("AW",_xlpm.minindex2,":AW300")), _xlpm.maxindex2, MIN(IF(_xlpm.fullcolumnrnge2="",ROW(_xlpm.fullcolumnrnge2)))-1, _xlpm.addminx2, INDIRECT(CONCATENATE("AW", _xlpm.minindex2,":BD", _xlpm.maxindex2)), _xlpm.minindex3, MATCH(Data_Constants!C15, $BJ$2:$BJ$300,0)+3, _xlpm.fullcolumnrnge3, INDIRECT(CONCATENATE("BJ",_xlpm.minindex3,":BJ300")), _xlpm.maxindex3, MIN(IF(_xlpm.fullcolumnrnge3="",ROW(_xlpm.fullcolumnrnge3)))-1, _xlpm.addminx3, INDIRECT(CONCATENATE("BJ", _xlpm.minindex3,":BN", _xlpm.maxindex3)), _xlpm.rnge1, IF(OR(ISBLANK(_xlpm.addminx1),(_xlfn.CHOOSECOLS(_xlpm.addminx1,1,2,5,6,7))="NA"),0,1), _xlpm.rnge2, IF(OR(ISBLANK(_xlpm.addminx2),(_xlpm.addminx2)="NA"),0,1), _xlpm.rnge3, IF(OR(ISBLANK(_xlpm.addminx3),(_xlpm.addminx3)="NA"),0,1), _xlpm.rnge4, IF(ISNUMBER(_xlpm.slaColumnrnge), IF(MOD(_xlpm.slaColumnrnge,1)=0, 1, 0), 0), _xlpm.rnge5, IF(ISNUMBER(_xlpm.uslaColumnrnge), IF(MOD(_xlpm.uslaColumnrnge,1)=0, 1, 0), 0), _xlpm.isSLAUSLAValid, IF(AND(MIN(_xlpm.rnge4)<>0, MIN(_xlpm.rnge5)<>0), IF(AND(_xlpm.uslaColumnrnge<=_xlpm.slaColumnrnge*1.6, _xlpm.uslaColumnrnge>=_xlpm.slaColumnrnge), 1, 0), 0), IF(AND(MIN(_xlpm.rnge1)=0,MIN(_xlpm.rnge2)=0,MIN(_xlpm.rnge3)=0),Data_Constants!D83, IF(AND(MIN(_xlpm.rnge1)=0,OR(MIN(_xlpm.rnge2)=1,MIN(_xlpm.rnge3)=1) ),Data_Constants!C83, IF(_xlpm.isSLAUSLAValid, Data_Constants!C39, Data_Constants!D39))))} | F13: =IF(OR(E13=Data_Constants!D39,E13=Data_Constants!D83,), FALSE, TRUE)
B14: 12 | C14: Response Times - Online Txns – Requirements | D14: =Data_Constants!C112 | E14: {=_xlfn.LET( _xlpm.minindex1, MATCH(Data_Constants!C11, $AJ$2:$AJ$300,0)+3, _xlpm.fullcolumnrnge1, INDIRECT(CONCATENATE("AJ",_xlpm.minindex1,":AJ300")), _xlpm.maxindex1, MIN(IF(_xlpm.fullcolumnrnge1="",ROW(_xlpm.fullcolumnrnge1)))-1, _xlpm.concusersColumnrnge, INDIRECT(CONCATENATE("AP",_xlpm.minindex1,":AP",_xlpm.maxindex1)), _xlpm.addminx1, INDIRECT(CONCATENATE("AJ", _xlpm.minindex1,":AP", _xlpm.maxindex1)), _xlpm.minindex2, MATCH(Data_Constants!C13, $AW$2:$AW$300,0)+3, _xlpm.fullcolumnrnge2, INDIRECT(CONCATENATE("AW",_xlpm.minindex2,":AW300")), _xlpm.maxindex2, MIN(IF(_xlpm.fullcolumnrnge2="",ROW(_xlpm.fullcolumnrnge2)))-1, _xlpm.addminx2, INDIRECT(CONCATENATE("AW", _xlpm.minindex2,":BD", _xlpm.maxindex2)), _xlpm.minindex3, MATCH(Data_Constants!C15, $BJ$2:$BJ$300,0)+3, _xlpm.fullcolumnrnge3, INDIRECT(CONCATENATE("BJ",_xlpm.minindex3,":BJ300")), _xlpm.maxindex3, MIN(IF(_xlpm.fullcolumnrnge3="",ROW(_xlpm.fullcolumnrnge3)))-1, _xlpm.addminx3, INDIRECT(CONCATENATE("BJ", _xlpm.minindex3,":BN", _xlpm.maxindex3)), _xlpm.rnge1, IF(OR(ISBLANK(_xlpm.addminx1),(_xlfn.CHOOSECOLS(_xlpm.addminx1,1,2,5,6,7))="NA"),0,1), _xlpm.rnge2, IF(OR(ISBLANK(_xlpm.addminx2),(_xlpm.addminx2)="NA"),0,1), _xlpm.rnge3, IF(OR(ISBLANK(_xlpm.addminx3),(_xlpm.addminx3)="NA"),0,1), _xlpm.rnge4, IF(ISNUMBER(_xlpm.concusersColumnrnge), IF(MOD(_xlpm.concusersColumnrnge,1)=0, 1, 0), 0), IF(AND(MIN(_xlpm.rnge1)=0,MIN(_xlpm.rnge2)=0,MIN(_xlpm.rnge3)=0),Data_Constants!D83, IF(AND(MIN(_xlpm.rnge1)=0,OR(MIN(_xlpm.rnge2)=1,MIN(_xlpm.rnge3)=1) ),Data_Constants!C83, IF(MIN(_xlpm.rnge4)=0, Data_Constants!D40, Data_Constants!C40))))} | F14: =IF(OR(E14=Data_Constants!D40,E14=Data_Constants!D83,), FALSE, TRUE)
B15: 13 | C15: Response Times - Online Txns – Requirements | D15: =Data_Constants!C113 | E15: {=_xlfn.LET( _xlpm.minindex1, MATCH(Data_Constants!C7, $V$2:$V$300,0)+3, _xlpm.fullcolumnrnge1, INDIRECT(CONCATENATE("V",_xlpm.minindex1,":V300")), _xlpm.maxindex1, MIN(IF(_xlpm.fullcolumnrnge1="",ROW(_xlpm.fullcolumnrnge1)))-1, _xlpm.peakallwconusersColumnrnge, INDIRECT(CONCATENATE("X",_xlpm.minindex1,":X",_xlpm.maxindex1)), _xlpm.minindex2, MATCH(Data_Constants!C11, $AJ$2:$AJ$300,0)+3, _xlpm.fullcolumnrnge2, INDIRECT(CONCATENATE("AJ",_xlpm.minindex2,":AJ300")), _xlpm.t_maxindex2, MIN(IF(_xlpm.fullcolumnrnge2="",ROW(_xlpm.fullcolumnrnge2)))-1, _xlpm.maxindex2, IF(_xlpm.t_maxindex2 < _xlpm.minindex2, _xlpm.minindex2, _xlpm.t_maxindex2), _xlpm.addminx2, INDIRECT(CONCATENATE("AJ", _xlpm.minindex2,":AP", _xlpm.maxindex2)), _xlpm.onlinetxnconusersColumnrnge, IF(_xlpm.t_maxindex2 < _xlpm.minindex2, 0, INDIRECT(CONCATENATE("AP",_xlpm.minindex2,":AP",_xlpm.maxindex2))), _xlpm.minindex3, MATCH(Data_Constants!C14, $BJ$2:$BJ$300,0)+3, _xlpm.fullcolumnrnge3, INDIRECT(CONCATENATE("BJ",_xlpm.minindex3,":BJ300")), _xlpm.t_maxindex3, MIN(IF(_xlpm.fullcolumnrnge3="",ROW(_xlpm.fullcolumnrnge3)))-1, _xlpm.maxindex3, IF(_xlpm.t_maxindex3 < _xlpm.minindex3, _xlpm.minindex3, _xlpm.t_maxindex3), _xlpm.onlinerptconusersColumnrnge, IF(_xlpm.t_maxindex3 < _xlpm.minindex3, 0, INDIRECT(CONCATENATE("BS",_xlpm.minindex3,":BS",_xlpm.maxindex3))), _xlpm.addminx3, INDIRECT(CONCATENATE("BJ", _xlpm.minindex3,":BN", _xlpm.maxindex3)), _xlpm.minindex4, MATCH(Data_Constants!C13, $AW$2:$AW$300,0)+3, _xlpm.fullcolumnrnge4, INDIRECT(CONCATENATE("AW",_xlpm.minindex4,":AW300")), _xlpm.maxindex4, MIN(IF(_xlpm.fullcolumnrnge4="",ROW(_xlpm.fullcolumnrnge4)))-1, _xlpm.addminx4, INDIRECT(CONCATENATE("AW", _xlpm.minindex4,":BD", _xlpm.maxindex4)), _xlpm.rnge1, IF(OR(ISBLANK(_xlpm.addminx2),(_xlfn.CHOOSECOLS(_xlpm.addminx2,1,2,5,6,7))="NA"),0,1), _xlpm.rnge2, IF(OR(ISBLANK(_xlpm.addminx3),(_xlpm.addminx3)="NA"),0,1), _xlpm.rnge3, IF(OR(ISBLANK(_xlpm.addminx4),(_xlpm.addminx4)="NA"),0,1), IF(AND(MIN(_xlpm.rnge1)=0,MIN(_xlpm.rnge2)=0,MIN(_xlpm.rnge3)=0),Data_Constants!D83, IF(AND(MIN(_xlpm.rnge1)=0,OR(MIN(_xlpm.rnge2)=1,MIN(_xlpm.rnge3)=1) ),Data_Constants!C83, IF(AND(ISNUMBER(_xlpm.peakallwconusersColumnrnge),ISNUMBER(_xlpm.onlinetxnconusersColumnrnge),ISNUMBER(_xlpm.onlinerptconusersColumnrnge)), IF(SUM(VALUE(_xlpm.peakallwconusersColumnrnge))=SUM(VALUE(_xlpm.onlinetxnconusersColumnrnge))+SUM(_xlpm.onlinerptconusersColumnrnge), Data_Constants!C41, Data_Constants!D41), Data_Constants!D41))))} | F15: =IF(OR(E15=Data_Constants!D41,E15=Data_Constants!D83,), FALSE, TRUE)
B16: 14 | C16: Response Times - Online Txns – Requirements | D16: =Data_Constants!C114 | E16: {=_xlfn.LET( _xlpm.minindex1, MATCH(Data_Constants!C11, $AJ$2:$AJ$300,0)+3, _xlpm.fullcolumnrnge1, INDIRECT(CONCATENATE("AJ",_xlpm.minindex1,":AJ300")), _xlpm.maxindex1, MIN(IF(_xlpm.fullcolumnrnge1="",ROW(_xlpm.fullcolumnrnge1)))-1, _xlpm.slaColumnrnge, INDIRECT(CONCATENATE("AN",_xlpm.minindex1,":AN",_xlpm.maxindex1)), _xlpm.remarksColumnrnge, INDIRECT(CONCATENATE("AT",_xlpm.minindex1,":AT",_xlpm.maxindex1)), _xlpm.addminx1, INDIRECT(CONCATENATE("AJ", _xlpm.minindex1,":AP", _xlpm.maxindex1)), _xlpm.minindex2, MATCH(Data_Constants!C13, $AW$2:$AW$300,0)+3, _xlpm.fullcolumnrnge2, INDIRECT(CONCATENATE("AW",_xlpm.minindex2,":AW300")), _xlpm.maxindex2, MIN(IF(_xlpm.fullcolumnrnge2="",ROW(_xlpm.fullcolumnrnge2)))-1, _xlpm.addminx2, INDIRECT(CONCATENATE("AW", _xlpm.minindex2,":BD", _xlpm.maxindex2)), _xlpm.minindex3, MATCH(Data_Constants!C15, $BJ$2:$BJ$300,0)+3, _xlpm.fullcolumnrnge3, INDIRECT(CONCATENATE("BJ",_xlpm.minindex3,":BJ300")), _xlpm.maxindex3, MIN(IF(_xlpm.fullcolumnrnge3="",ROW(_xlpm.fullcolumnrnge3)))-1, _xlpm.addminx3, INDIRECT(CONCATENATE("BJ", _xlpm.minindex3,":BN", _xlpm.maxindex3)), _xlpm.rnge1, IF(OR(ISBLANK(_xlpm.addminx1),(_xlfn.CHOOSECOLS(_xlpm.addminx1,1,2,5,6,7))="NA"),0,1), _xlpm.rnge2, IF(OR(ISBLANK(_xlpm.addminx2),(_xlpm.addminx2)="NA"),0,1), _xlpm.rnge3, IF(OR(ISBLANK(_xlpm.addminx3),(_xlpm.addminx3)="NA"),0,1), _xlpm.rnge4, IF(_xlpm.slaColumnrnge=0, 0,1), _xlpm.rnge5, IF(_xlpm.slaColumnrnge<=5, 1,0), _xlpm.rnge6, IF(_xlpm.slaColumnrnge>5, IF(LEN(_xlpm.remarksColumnrnge)>=10, 1,0),1), IF(AND(MIN(_xlpm.rnge1)=0,MIN(_xlpm.rnge2)=0,MIN(_xlpm.rnge3)=0),Data_Constants!D83, IF(AND(MIN(_xlpm.rnge1)=0,OR(MIN(_xlpm.rnge2)=1,MIN(_xlpm.rnge3)=1) ),Data_Constants!C83, IF(MIN(_xlpm.rnge4)=0, Data_Constants!D37, IF(MIN(_xlpm.rnge5)=1, Data_Constants!C68, IF(MIN(_xlpm.rnge5)=0, IF(MIN(_xlpm.rnge6)=0, Data_Constants!D42, Data_Constants!C42)))))))} | F16: =IF(OR(E16=Data_Constants!D42,E16=Data_Constants!D37,E16=Data_Constants!D83,), FALSE, TRUE)
B17: 15 | C17: Response Times - Batch Jobs – Requirements | D17: =Data_Constants!C118 | E17: {=_xlfn.LET( _xlpm.minindex1, MATCH(Data_Constants!C11, $AJ$2:$AJ$300,0)+3, _xlpm.fullcolumnrnge1, INDIRECT(CONCATENATE("AJ",_xlpm.minindex1,":AJ300")), _xlpm.maxindex1, MIN(IF(_xlpm.fullcolumnrnge1="",ROW(_xlpm.fullcolumnrnge1)))-1, _xlpm.addminx1, INDIRECT(CONCATENATE("AJ", _xlpm.minindex1,":AP", _xlpm.maxindex1)), _xlpm.minindex3, MATCH(Data_Constants!C15, $BJ$2:$BJ$300,0)+3, _xlpm.fullcolumnrnge3, INDIRECT(CONCATENATE("BJ",_xlpm.minindex3,":BJ300")), _xlpm.maxindex3, MIN(IF(_xlpm.fullcolumnrnge3="",ROW(_xlpm.fullcolumnrnge3)))-1, _xlpm.addminx3, INDIRECT(CONCATENATE("BJ", _xlpm.minindex3,":BN", _xlpm.maxindex3)), _xlpm.minindex2, MATCH(Data_Constants!C13, $AW$2:$AW$300,0)+3, _xlpm.fullcolumnrnge2, INDIRECT(CONCATENATE("AW",_xlpm.minindex2,":AW300")), _xlpm.maxindex2,MIN(IF(_xlpm.fullcolumnrnge2="",ROW(_xlpm.fullcolumnrnge2)))-1, _xlpm.addminx2, INDIRECT(CONCATENATE("AW", _xlpm.minindex2,":BD", _xlpm.maxindex2)), _xlpm.avgtimeforbatchColumnrnge, INDIRECT(CONCATENATE("AZ",_xlpm.minindex2,":AZ",_xlpm.maxindex2)), _xlpm.timeval, IF(NOT(ISERROR(FIND(Data_Constants!I11, _xlpm.avgtimeforbatchColumnrnge))), CONVERT(LEFT(_xlpm.avgtimeforbatchColumnrnge, FIND(Data_Constants!I11, _xlpm.avgtimeforbatchColumnrnge)-2), "min", Data_Constants!I13), IF(NOT(ISERROR(FIND(Data_Constants!I10, _xlpm.avgtimeforbatchColumnrnge))), CONVERT(LEFT(_xlpm.avgtimeforbatchColumnrnge, FIND(Data_Constants!I10, _xlpm.avgtimeforbatchColumnrnge)-2), "hr", Data_Constants!I13), IF(NOT(ISERROR(FIND(Data_Constants!I12, _xlpm.avgtimeforbatchColumnrnge))), CONVERT(LEFT(_xlpm.avgtimeforbatchColumnrnge, FIND(Data_Constants!I12, _xlpm.avgtimeforbatchColumnrnge)-2), "sec", Data_Constants!I13)))), _xlpm.rnge1, IF(OR(ISBLANK(_xlpm.addminx1),(_xlfn.CHOOSECOLS(_xlpm.addminx1,1,2,5,6,7))="NA"),0,1), _xlpm.rnge3, IF(OR(ISBLANK(_xlpm.addminx3),(_xlpm.addminx3)="NA"),0,1), _xlpm.rnge2, IF(OR(ISBLANK(_xlpm.addminx2),(_xlpm.addminx2)="NA"),0,1), _xlpm.rnge4, IF(_xlpm.timeval>=60, 1, 0), IF(AND(MIN(_xlpm.rnge1)=0,MIN(_xlpm.rnge2)=0,MIN(_xlpm.rnge3)=0),Data_Constants!D65, IF(AND(MIN(_xlpm.rnge2)=0,OR(MIN(_xlpm.rnge1)=1,MIN(_xlpm.rnge3)=1) ),Data_Constants!C65, IF(AND(MIN(_xlpm.rnge2)=1, MIN(_xlpm.rnge4)=1),Data_Constants!C43, Data_Constants!D43))))} | F17: =IF(OR(E17=Data_Constants!D43,E17=Data_Constants!D65), FALSE, TRUE) | I17: =IF(AND(F3:F22, K3:K4), Data_Constants!C51,Data_Constants!D51)
B18: 16 | C18: Response Times - Reports – Requirements | D18: =Data_Constants!C122 | E18: {=_xlfn.LET( _xlpm.minindex1, MATCH(Data_Constants!C11, $AJ$2:$AJ$300,0)+3, _xlpm.fullcolumnrnge1, INDIRECT(CONCATENATE("AJ",_xlpm.minindex1,":AJ300")), _xlpm.maxindex1, MIN(IF(_xlpm.fullcolumnrnge1="",ROW(_xlpm.fullcolumnrnge1)))-1, _xlpm.addminx1, INDIRECT(CONCATENATE("AJ", _xlpm.minindex1,":AP", _xlpm.maxindex1)), _xlpm.minindex2, MATCH(Data_Constants!C13, $AW$2:$AW$300,0)+3, _xlpm.fullcolumnrnge2, INDIRECT(CONCATENATE("AW",_xlpm.minindex2,":AW300")), _xlpm.maxindex2, MIN(IF(_xlpm.fullcolumnrnge2="",ROW(_xlpm.fullcolumnrnge2)))-1, _xlpm.addminx2, INDIRECT(CONCATENATE("AW", _xlpm.minindex2,":BD", _xlpm.maxindex2)), _xlpm.minindex3, MATCH(Data_Constants!C15, $BJ$2:$BJ$300,0)+3, _xlpm.fullcolumnrnge3, INDIRECT(CONCATENATE("BJ",_xlpm.minindex3,":BJ300")), _xlpm.maxindex3, MIN(IF(_xlpm.fullcolumnrnge3="",ROW(_xlpm.fullcolumnrnge3)))-1, _xlpm.reporttypeColumnrnge, INDIRECT(CONCATENATE("BL",_xlpm.minindex3,":BL",_xlpm.maxindex3)), _xlpm.addminx3, INDIRECT(CONCATENATE("BJ", _xlpm.minindex3,":BN", _xlpm.maxindex3)), _xlpm.rnge1, IF(OR(ISBLANK(_xlpm.addminx1),(_xlfn.CHOOSECOLS(_xlpm.addminx1,1,2,5,6,7))="NA"),0,1), _xlpm.rnge2, IF(OR(ISBLANK(_xlpm.addminx2),(_xlpm.addminx2)="NA"),0,1), _xlpm.rnge3, IF(OR(ISBLANK(_xlpm.addminx3),(_xlpm.addminx3)="NA"),0,1), _xlpm.rnge4, IF(COUNTIF(Data_Constants!$H$17:$H$18,_xlpm.reporttypeColumnrnge)=1, 1, 0), IF(AND(MIN(_xlpm.rnge1)=0,MIN(_xlpm.rnge2)=0,MIN(_xlpm.rnge3)=0),Data_Constants!D56, IF(AND(MIN(_xlpm.rnge3)=0,OR(MIN(_xlpm.rnge1)=1,MIN(_xlpm.rnge2)=1) ),Data_Constants!C56, IF(AND(MIN(_xlpm.rnge3)=1, MIN(_xlpm.rnge4)=1),Data_Constants!C44, Data_Constants!D44))))} | F18: =IF(OR(E18=Data_Constants!D44,E18=Data_Constants!D56), FALSE, TRUE)
